2022-05-27 09:40:46.960889: W tensorflow/stream_executor/platform/default/dso_loader.cc:64] Could not load dynamic library 'libcudart.so.11.0'; dlerror: libcudart.so.11.0: cannot open shared object file: No such file or directory
2022-05-27 09:40:46.960907: I tensorflow/stream_executor/cuda/cudart_stub.cc:29] Ignore above cudart dlerror if you do not have a GPU set up on your machine.
2022-05-27 09:40:47.805264: I tensorflow/stream_executor/platform/default/dso_loader.cc:53] Successfully opened dynamic library libcuda.so.1
2022-05-27 09:40:47.832514: I tensorflow/stream_executor/cuda/cuda_gpu_executor.cc:937] successful NUMA node read from SysFS had negative value (-1), but there must be at least one NUMA node, so returning NUMA node zero
2022-05-27 09:40:47.832791: I tensorflow/core/common_runtime/gpu/gpu_device.cc:1733] Found device 0 with properties: 
pciBusID: 0000:01:00.0 name: NVIDIA GeForce GTX 1050 Ti computeCapability: 6.1
coreClock: 1.392GHz coreCount: 6 deviceMemorySize: 3.94GiB deviceMemoryBandwidth: 104.43GiB/s
2022-05-27 09:40:47.832899: W tensorflow/stream_executor/platform/default/dso_loader.cc:64] Could not load dynamic library 'libcudart.so.11.0'; dlerror: libcudart.so.11.0: cannot open shared object file: No such file or directory
2022-05-27 09:40:47.832955: W tensorflow/stream_executor/platform/default/dso_loader.cc:64] Could not load dynamic library 'libcublas.so.11'; dlerror: libcublas.so.11: cannot open shared object file: No such file or directory
2022-05-27 09:40:47.833023: W tensorflow/stream_executor/platform/default/dso_loader.cc:64] Could not load dynamic library 'libcublasLt.so.11'; dlerror: libcublasLt.so.11: cannot open shared object file: No such file or directory
2022-05-27 09:40:47.834237: I tensorflow/stream_executor/platform/default/dso_loader.cc:53] Successfully opened dynamic library libcufft.so.10
2022-05-27 09:40:47.834490: I tensorflow/stream_executor/platform/default/dso_loader.cc:53] Successfully opened dynamic library libcurand.so.10
2022-05-27 09:40:47.834567: W tensorflow/stream_executor/platform/default/dso_loader.cc:64] Could not load dynamic library 'libcusolver.so.11'; dlerror: libcusolver.so.11: cannot open shared object file: No such file or directory
2022-05-27 09:40:47.834637: W tensorflow/stream_executor/platform/default/dso_loader.cc:64] Could not load dynamic library 'libcusparse.so.11'; dlerror: libcusparse.so.11: cannot open shared object file: No such file or directory
2022-05-27 09:40:47.834698: W tensorflow/stream_executor/platform/default/dso_loader.cc:64] Could not load dynamic library 'libcudnn.so.8'; dlerror: libcudnn.so.8: cannot open shared object file: No such file or directory
2022-05-27 09:40:47.834719: W tensorflow/core/common_runtime/gpu/gpu_device.cc:1766] Cannot dlopen some GPU libraries. Please make sure the missing libraries mentioned above are installed properly if you would like to use GPU. Follow the guide at https://www.tensorflow.org/install/gpu for how to download and setup the required libraries for your platform.
Skipping registering GPU devices...
2022-05-27 09:40:47.834934: I tensorflow/core/platform/cpu_feature_guard.cc:142] This TensorFlow binary is optimized with oneAPI Deep Neural Network Library (oneDNN) to use the following CPU instructions in performance-critical operations:  AVX2 FMA
To enable them in other operations, rebuild TensorFlow with the appropriate compiler flags.
2022-05-27 09:40:47.835261: I tensorflow/core/common_runtime/gpu/gpu_device.cc:1258] Device interconnect StreamExecutor with strength 1 edge matrix:
2022-05-27 09:40:47.835270: I tensorflow/core/common_runtime/gpu/gpu_device.cc:1264]      
Convert model v49/Real_relu_pions_25_30_best_model.h5 to v49/Real_relu_pions_25_30_best_model.h5.onnx
Traceback (most recent call last):
  File "ConvertList.py", line 25, in <module>
    model = tf.keras.models.load_model(inp)
  File "/home/henry/.local/lib/python3.8/site-packages/tensorflow/python/keras/saving/save.py", line 201, in load_model
    return hdf5_format.load_model_from_hdf5(filepath, custom_objects,
  File "/home/henry/.local/lib/python3.8/site-packages/tensorflow/python/keras/saving/hdf5_format.py", line 198, in load_model_from_hdf5
    model.compile(**saving_utils.compile_args_from_training_config(
  File "/home/henry/.local/lib/python3.8/site-packages/tensorflow/python/keras/saving/saving_utils.py", line 213, in compile_args_from_training_config
    loss = _deserialize_nested_config(losses.deserialize, loss_config)
  File "/home/henry/.local/lib/python3.8/site-packages/tensorflow/python/keras/saving/saving_utils.py", line 254, in _deserialize_nested_config
    return deserialize_fn(config)
  File "/home/henry/.local/lib/python3.8/site-packages/tensorflow/python/keras/losses.py", line 2033, in deserialize
    return deserialize_keras_object(
  File "/home/henry/.local/lib/python3.8/site-packages/tensorflow/python/keras/utils/generic_utils.py", line 698, in deserialize_keras_object
    raise ValueError(
ValueError: Unknown loss function: weighted_mean_squared_error. Please ensure this object is passed to the `custom_objects` argument. See https://www.tensorflow.org/guide/keras/save_and_serialize#registering_the_custom_object for details.
